Workbook

Sheet Notes de correction
A1: NOTES DE CORRECTION — Plan d'affaires Boubacar COULIBALY (Zéré Kènè & Délice)
A2: Observations APEJ/DEJ : corrections apportées au modèle Excel (méthode de calcul). Les hypothèses (montants, prix, rendements) ne sont pas modifiées.
A4: # | B4: Emplacement (feuille!cellule) | C4: Observation | D4: Correction apportée | E4: Effet
A5: 1 | B5: Ratios d'analyse!B21:B30 | C5: Seuil de rentabilité : amortissements omis des charges fixes ; données de l'année 3 et de l'année 4 mélangées. | D5: Charges fixes = personnel, impôts, frais financiers et amortissements de l'année 3 ; seuil de l'année 1 ajouté (ligne 30). | E5: Seuil relevé (plus prudent).
A6: 2 | B6: Ratios d'analyse!B6:D11 | C6: Valeur ajoutée : impôts et taxes comptés deux fois. | D6: VA = personnel + amortissements + frais financiers + résultat brut (= CA − achats − TFSE − autres charges). Les impôts sont exclus. | E6: VA légèrement plus faible.
A7: 3 | B7: Compte d'exploitation!E14:F14 | C7: Amortissements des années 4 et 5 repris par formule fixe de l'année 2 (biens déjà amortis). | D7: Amortissements AN4 et AN5 calculés bien par bien (Eléments!G65:H92), plafonnés à la valeur du bien. | E7: Résultat net AN4-AN5 corrigé ; la CAF n'est pas modifiée.
A8: 4 | B8: Compte de tresorerie!A36:F37 | C8: Ligne « Ressources actualisées à 10 % » : simple réduction de 10 %, sans actualisation, non utilisée. | D8: Ligne supprimée. Le délai actualisé reste calculé à 8 % (lignes 44 à 51). | E8: Aucun effet sur les résultats.
A9: 5 | B9: Echéancier Prêt!C4 | C9: Taux TTC affiché 9 % (arrondi) alors qu'il est de 9,36 % (8 % × 1,17). | D9: Format d'affichage à 2 décimales. | E9: Affichage.
A10: 6 | B10: Ratios d'analyse!A39 | C10: « Taux de rentabilité financière » : ce ratio est une marge nette. | D10: Intitulé corrigé : « taux de marge nette ». | E10: Intitulé.
A11: 7 | B11: Compte d'exploitation!A9 | C11: Le poste « Achats de matières premières » inclut aussi carburant, emballages et eau. | D11: Intitulé : « Achats (matières premières et autres achats) ». Le plan présente les deux tableaux séparément. | E11: Intitulé.
A12: 8 | B12: Fiche Signalétique!C13 | C12: Institution financière héritée d'un autre dossier. | D12: Remplacée par « (à renseigner) ». | E12: Fiche.
A14: Points restant à arbitrer (modifient les hypothèses : non appliqués sans validation)
A15: 1 | B15: Besoin en fonds de roulement : à recalculer sur le besoin réel du cycle (intrants, salaires de campagne, frais généraux, intérêts du différé).
A16: 2 | B16: Paillage, préparation du terrain, gaine goutte-à-goutte : consommables à reclasser en charges annuelles ; taux d'amortissement du bassin et des panneaux à revoir (10 %).
A17: 3 | B17: Taux d'actualisation : 10 à 12 % (coût d'opportunité) au lieu de 8 % ; renouvellement des équipements à prévoir.
A18: 4 | B18: Rémunération du promoteur : prélèvements personnels ou rémunération forfaitaire.
A19: 5 | B19: Impôt sur les bénéfices forcé à zéro (Compte d'exploitation!B18:F18) : justifier le régime fiscal.
A20: 6 | B20: Plan de trésorerie et compte d'exploitation mensuels : répartition en douzièmes égaux à remplacer par la saisonnalité réelle (récolte, intrants au démarrage).
A21: 7 | B21: Échéancier de remboursement : à caler sur le cycle agricole avec l'institution financière.

Sheet Hypothèse de base
A2: HYPOTHESES DE BASE
A4: I. ACHAT DE MATIERES PREMIERES
A6: Désignation | B6: Unité | C6: Qté/jour | D6: Qté/Sme | E6: Qté/mois | F6: Qté/Trim | G6: Qté/an | H6: PU | I6: Montant
A7: Semence pastèque | B7: Boîte | C7: 0 | D7: =E7/4 -> 0 | E7: =C7*25 -> 0 | F7: 0 | G7: 6 | H7: 70000 | I7: =G7*H7 -> 420000
A8: Engrais NPK 50 kg | B8: Sac | C8: 0 | D8: =E8/4 -> 0 | E8: =C8*25 -> 0 | F8: 0 | G8: 18 | H8: 25000 | I8: =G8*H8 -> 450000
A9: Intrant Urée 50 kg | B9: Sac | F9: 0 | G9: 9 | H9: 20000 | I9: =G9*H9 -> 180000
A10: Fongicide + insecticide | B10: Boîte | E10: 0 | F10: 0 | G10: 6 | H10: 60000 | I10: =G10*H10 -> 360000
A11: Fumure organique | B11: Sac | C11: 0 | F11: 0 | G11: 60 | H11: 1000 | I11: =G11*H11 -> 60000
A12: 0 | B12: 0 | E12: 0 | F12: 0 | G12: =F12*4 -> 0 | H12: 0 | I12: =G12*H12 -> 0
A13: TOTAL | D13: =SUM(D7:D9) -> 0 | E13: =SUM(E7:E9) -> 0 | F13: 0 | G13: 0 | I13: =SUM(I7:I12) -> 1470000 | K13: =I13/12 -> 122500
K14: =K13*3 -> 367500
A15: I. AUTRES CHATS DE MATIERES PREMIERES | L15: =I13/12 -> 122500
A17: Désignation | B17: Unité | C17: Qté/jour | D17: Qté/Sme | E17: Qté/mois | F17: Qté/Trim | G17: Qté/an | H17: PU | I17: Montant
A18: Carburant / énergie | B18: Forfait | C18: 0 | D18: =E18/4 -> 0 | E18: 0 | F18: 0 | G18: 1 | H18: 300000 | I18: =G18*H18 -> 300000
A19: Emballages (sacs, caisses) | B19: Lot | E19: 0 | F19: =E19*3 -> 0 | G19: 1 | H19: 100000 | I19: =G19*H19 -> 100000
A20: Eau d'irrigation | B20: Forfait | G20: 1 | H20: 50000 | I20: =G20*H20 -> 50000 | L20: =L19/2 -> 0
I21: =+H21*F21 -> 0
I22: =+H22*F22 -> 0
A23: TOTAL | D23: =SUM(D18:D20) -> 0 | E23: =SUM(E18:E20) -> 0 | F23: =SUM(F18:F20) -> 0 | G23: =SUM(G18:G20) -> 3 | I23: =SUM(I18:I22) -> 450000
A26: II. DONNEES PREVISIONNELLES SUR LES AUTRES CHARGES MENSUELLES
A28: 2.1. FRAIS DE PERSONNEL
C29: 12
A30: Noms et Prénoms | B30: Permanent | D30: Temporaire | F30: Salaire mensuel | G30: Nbre de mois/an | H30: Montant
B31: Homme | C31: Femme | D31: Homme | E31: Femme | H31: annuel
A32: PROMOTEUR - Boubacar COULIBALY | B32: 1 | D32: 0 | F32: 50000 | G32: 12 | H32: =+G32*F32*SUM(B32:E32) -> 600000
A33: TECHNICIEN AGRONOME | B33: 1 | D33: 0 | F33: 50000 | G33: 12 | H33: =+G33*F33*SUM(B33:E33) -> 600000
A34: OUVRIERS SAISONNIERS | B34: 0 | C34: 0 | D34: 3 | F34: 50000 | G34: 6 | H34: =+G34*F34*SUM(B34:E34) -> 900000 | M34: =H38/12 -> 175000
A35: 0 | B35: 0 | C35: 0 | D35: 0 | F35: 0 | G35: 0 | H35: =+G35*F35*SUM(B35:E35) -> 0
A36: 0 | B36: 0 | C36: 0 | D36: 0 | F36: 0 | G36: 0 | H36: =+G36*F36*SUM(B36:E36) -> 0
H37: =+G37*F37*SUM(B37:E37) -> 0
A38: Total | B38: =SUM(B32:B37) -> 2 | C38: =SUM(C32:C37) -> 0 | D38: =SUM(D32:D37) -> 3 | E38: =SUM(E32:E37) -> 0 | H38: =SUM(H32:H37) -> 2100000
A40: 2.2. Construction d'infrastructures
A42: Désignation | B42: Quantité | C42: Prix unitaire | D42: Montant (F.CFA)
A43: 0 | B43: 0 | C43: 0 | D43: 0
A44: 0 | B44: 0 | C44: 0 | D44: 0
A45: 0 | B45: 0 | C45: 0 | D45: 0
D46: =+B46*C46 -> 0
D47: =+B47*C47 -> 0
D48: =+B48*C48 -> 0
A49: TOTAL | D49: =D44+D43+D45 -> 0
...

Sheet Coût du projet
A2: A. EVALUATION DU COÛT DE PROJET (FCFA) | B2: Montant FCFA | D2: %
A4: 1. Frais d'établissement | C4: =SUM(B5:B10) -> 15000 | D4: =C4/$C$46 -> 0.003
A5: Frais d'étude / développement
A6: Frais de publicité et de lancement | B6: 0
A7: Frais de constitution | B7: 15000
A8: Frais d'hypothèque
A9: Frais de nantissement
A10: Autres frais
A11: 2. Frais d'investissement | C11: =B12+B19+B28+B34 -> 3985000 | D11: =C11/$C$46 -> 0.797
A12: 2.1 Constructions | B12: =SUM(B13:B18) -> 0
A13: ='Hypothèse de base'!A43 -> 0 | B13: =+'Hypothèse de base'!D43 -> 0
A14: =+'Hypothèse de base'!A44 -> 0 | B14: =+'Hypothèse de base'!D44 -> 0
A15: =+'Hypothèse de base'!A45 -> 0 | B15: =+'Hypothèse de base'!D45 -> 0
A16: =+'Hypothèse de base'!A46 -> 0 | B16: =+'Hypothèse de base'!D46 -> 0
A17: =+'Hypothèse de base'!A47 -> 0 | B17: =+'Hypothèse de base'!D47 -> 0
A18: =+'Hypothèse de base'!A48 -> 0 | B18: =+'Hypothèse de base'!D48 -> 0
A19: 2.2 Agencement-Aménagement-Installations | B19: =SUM(B20:B27) -> 3085000
A20: =+'Hypothèse de base'!A54 -> Aménagement préparatoire | B20: =+'Hypothèse de base'!D54 -> 45000
A21: ='Hypothèse de base'!A55 -> Formation des billons | B21: =+'Hypothèse de base'!D55 -> 60000
A22: ='Hypothèse de base'!A56 -> Système goutte-à-goutte | B22: =+'Hypothèse de base'!D56 -> 750000
A23: =+'Hypothèse de base'!A57 -> Clôture en grillage 0,75 ha | B23: =+'Hypothèse de base'!D57 -> 1000000
A24: ='Hypothèse de base'!A58 -> Bassin 40 m³ | B24: ='Hypothèse de base'!D58 -> 250000
A25: ='Hypothèse de base'!A59 -> Puits à grand diamètre | B25: ='Hypothèse de base'!D59 -> 980000
A26: ='Hypothèse de base'!A60 -> 0 | B26: ='Hypothèse de base'!D60 -> 0
A27: ='Hypothèse de base'!A61 -> 0 | B27: ='Hypothèse de base'!D61 -> 0
A28: 2.3 Mobiliers et matériels | B28: =SUM(B29:B33) -> 20000
A29: =+'Hypothèse de base'!A68 -> Balance | B29: =+'Hypothèse de base'!D68 -> 20000
A30: =+'Hypothèse de base'!A69 -> 0 | B30: =+'Hypothèse de base'!D69 -> 0
A31: =+'Hypothèse de base'!A70 -> 0 | B31: =+'Hypothèse de base'!D70 -> 0
A32: =+'Hypothèse de base'!A71 -> 0 | B32: =+'Hypothèse de base'!D71 -> 0
A33: =+'Hypothèse de base'!A72 -> 0 | B33: =+'Hypothèse de base'!D72 -> 0
A34: 2.4 Equipements de production | B34: =SUM(B35:B39) -> 880000
A35: =+'Hypothèse de base'!A78 -> Paillage en plastique | B35: =+'Hypothèse de base'!D78 -> 400000
A36: =+'Hypothèse de base'!A79 -> Pulvérisateurs | B36: =+'Hypothèse de base'!D79 -> 75000
A37: =+'Hypothèse de base'!A80 -> Brouettes + Houes | B37: =+'Hypothèse de base'!D80 -> 60000
A38: =+'Hypothèse de base'!A81 -> P 17 (2000 m) | B38: =+'Hypothèse de base'!D81 -> 300000
A39: ='Hypothèse de base'!A82 -> Outils divers (dabas, pioches, pelles) | B39: ='Hypothèse de base'!D82 -> 45000
A40: 3. Besoin en fonds de roulement | C40: =SUM(B41:B45) -> 1000000 | D40: =C40/$C$46 -> 0.2
A41: Achats de matières premières (3 mois) | B41: =('Hypothèse de base'!I13+'Hypothèse de base'!I23)/4 -> 480000 | F41: 1
A42: Autres achat (préciser le nombre de mois) | B42: 0 | F42: 1
...

Sheet Plan Financement
A2: B. PLAN DE FINANCEMENT | E2: Homme | F2: Apport numeraire | G2: - | H2: 0.1 | W2: Primes | AC2: Avant CS
E3: Verdissement | F3: Subvention "Emploi" | G3: Non | H3: =+IF(G3=$AC$11,$R$5,0) -> 0 | R3: =+IF(E3=S4,IF(E2=T4,U4,0),0)+IF(E3=S4,IF(E2=T5,U5),0)+IF(E3=S6,IF(E2=T6,U6,0),0)+IF(E3=S6,IF(E2=T7,U7,0),0)+IF(E3=S8,IF(E2=T4,U8,U8),0)+IF(E3=S9,IF(E2=T4,U8,U9),0) -> 0.05 | U3: Apport numeraire | V3: crédit | W3: Emploi | X3: Innovation | Y3: Crédit | Z3: Subvention | AC3: Création
A4: 1. Le coût total de projet | B4: =+B7+B10+B14 -> 1 | C4: ='Coût du projet'!C46 -> 5000000 | F4: Subvention "Innovation" | G4: Non | H4: =+IF(G4=$AC$11,$R$6,0) -> 0 | S4: Création | T4: Homme | U4: 0.05 | W4: 0.25 | X4: 0.25 | Y4: 0.25 | AC4: Croissance
F5: Crédit Ifs | G5: - | H5: =+IF(E3=S4,R8,0)+IF(E3=S6,R8,0)+IF(E3=S8,V8,0)+IF(E3=S9,(R8-H6),0) -> 0.6 | R5: =+IF(E3=S4,IF(E2=T4,W4),0)+IF(E3=S4,IF(E2=T5,W5),0)+IF(E3=S6,IF(E2=T6,W4),0)+IF(E3=S6,IF(E2=T7,W7),0)+IF(E2=S10,U10,0)+IF(E3=S9,IF(E2=T4,W4,0))+IF(E3=S9,IF(E2=T5,W5,0)) -> 0.25 | T5: Femme | U5: 0.05 | W5: 0.3 | X5: 0.3 | Y5: 0.3 | AC5: Projet vert
A6: 2. Le financement de projet | F6: Subvention | G6: - | H6: =+IF(E3=S8,Z8,0)+IF(E3=S9,Z9,0) -> 0.3 | R6: =+IF(E3=S4,IF(E2=T4,X4),0)+IF(E3=S4,IF(E2=T5,X5),0)+IF(E3=S6,IF(E2=T6,X4),0)+IF(E3=S6,IF(E2=T7,X7),0)+IF(E3=S9,IF(E2=T4,W4,0))+IF(E3=S9,IF(E2=T5,X5,0)) -> 0.25 | S6: Croissance | T6: Homme | U6: 0.1 | W6: 0.25 | X6: 0.25 | Y6: 0.25 | AC6: Verdissement
A7: 2.1 L'apport personnel | B7: =+SUM(B8:B9) -> 0.1 | C7: =SUM(C8:C9) -> 500000 | F7: Prime "Emprunt" | G7: Non | H7: =+IF(G7=$AC$11,$R$7,0) -> 0 | Q7: =+Y9-H3-H4-H7 -> 0 | R7: =+IF(E3=S4,IF(E2=T4,Y4),0)+IF(E3=S4,IF(E2=T5,Y5),0)+IF(E3=S6,IF(E2=T6,Y4),0)+IF(E3=S6,IF(E2=T7,Y7),0)+IF(E3=S9,IF(E2=T4,W4,0))+IF(E3=S9,IF(E2=T5,W5,0)) -> 0.25 | T7: Femme | U7: 0.1 | W7: 0.3 | X7: 0.3 | Y7: 0.3
A8: Apport en numéraire | B8: =+H2 -> 0.1 | C8: =B8*C4 -> 500000 | Q8: =+Q7 -> 0 | R8: =100%-H2-H3-H4 -> 0.9 | S8: Projet Vert | U8: 0.05 | V8: 0.25 | Z8: 0.7 | AC8: Homme
Q9: =+R10 -> 0.3 | S9: Verdissement | U9: 0.05 | V9: 0.65 | Z9: 0.3 | AC9: Femme
A10: 2.2 La contribution (Primes) du FACEJ | B10: =+SUM(B11:B13) -> 0.3 | C10: =+SUM(C11:C13) -> 1500000 | R10: 0.3 | S10: Avant CS | T10: Homme | U10: 0
A11: Subvention « création emploi » | B11: =C11/C4 -> 0 | C11: =IF((H3*$C$4)<=1000000,(H3*$C$4),1000000) -> 0 | T11: Femme | AC11: Oui
A12: Subvention « innovants» | B12: =+C12/C4 -> 0 | C12: =IF((H4*$C$4)<=1000000,(H4*$C$4),1000000) -> 0 | AC12: Non
A13: Subvention (Projets verts et Verdissement) | B13: =+H6 -> 0.3 | C13: =B13*$C$4 -> 1500000
A14: 2.3 Le crédit sollicité | B14: =+B15 -> 0.6 | C14: =+C15 -> 3000000 | AC14: An
A15: Financement IFPs | B15: =+H5 -> 0.6 | C15: =C4-C7-C10 -> 3000000 | AC15: Trimestre
A16: Vérification | C16: =C4=C7+C10+C14 -> TRUE | AC16: Mois
A17: Prime « emprunt » (à débloquer après remboursement intégral du prêt) | B17: =+H7 -> 0 | C17: =IF((H7*$C$4)<=1000000,(H7*$C$4),1000000) -> 0
A18: Conditions de financement des IFS
A19: Durée du prêt | B19: 36 | C19: Mois
A20: Taux d'interet | B20: 0.08 | C20: An
A21: Différé | B21: 3 | C21: mois
A22: Échéance de paiement | B22: 36 | C22: mois
A23: TAF | B23: 0.17

Sheet Feuil3

Sheet Eléments du compte d'exploitati
A2: C. ELEMENTS DU COMPTE D'EXPLOITATION PREVISIONNEL (FCFA)
A4: 1. Recettes prévisionnelles
A5: Taux de croissance | B5: 0 | C5: 0.02 | D5: 0.02 | E5: 0.02 | F5: 0.02
A6: Désignations/Années | B6: AN1 | C6: AN2 | D6: AN3 | E6: AN4 | F6: AN5
A7: =+'Hypothèse de base'!A106 -> Vente pastèque gros calibre | B7: =+'Hypothèse de base'!I106 -> 5600000 | C7: =B7+(B7*$C$5) -> 5712000 | D7: =C7+(C7*$D$5) -> 5826240 | E7: =D7+(D7*$E$5) -> 5942764.8 | F7: =E7+(E7*$F$5) -> 6061620.1
A8: =+'Hypothèse de base'!A107 -> Vente pastèque moyen calibre | B8: =+'Hypothèse de base'!I107 -> 1800000 | C8: =B8+(B8*$C$5) -> 1836000 | D8: =C8+(C8*$D$5) -> 1872720 | E8: =D8+(D8*$E$5) -> 1910174.4 | F8: =E8+(E8*$F$5) -> 1948377.9
A9: =+'Hypothèse de base'!A108 -> 0 | B9: =+'Hypothèse de base'!I108 -> 0 | C9: =B9+(B9*$C$5) -> 0 | D9: =C9+(C9*$D$5) -> 0 | E9: =D9+(D9*$E$5) -> 0 | F9: =E9+(E9*$F$5) -> 0
A10: =+'Hypothèse de base'!A109 -> 0 | B10: =+'Hypothèse de base'!I109 -> 0 | C10: =B10+(B10*$C$5) -> 0 | D10: =C10+(C10*$D$5) -> 0 | E10: =D10+(D10*$E$5) -> 0 | F10: =E10+(E10*$F$5) -> 0
A11: =+'Hypothèse de base'!A113 -> 0 | B11: =+'Hypothèse de base'!I113 -> 0 | C11: =B11+(B11*$C$5) -> 0 | D11: =C11+(C11*$D$5) -> 0 | E11: =D11+(D11*$E$5) -> 0 | F11: =E11+(E11*$F$5) -> 0
A12: Total recettes | B12: =SUM(B7:B11) -> 7400000 | C12: =SUM(C7:C11) -> 7548000 | D12: =SUM(D7:D11) -> 7698960 | E12: =SUM(E7:E11) -> 7852939.2 | F12: =SUM(F7:F11) -> 8009998
A14: 2. Charges d'exploitation
A16: 2.1 Achats | B16: 0 | C16: 0.06 | D16: 0.08 | E16: =D16 -> 0.08 | F16: =E16 -> 0.08
A17: Désignations/Années | B17: AN1 | C17: AN2 | D17: AN3 | E17: AN4 | F17: AN5
A18: =+'Hypothèse de base'!A7 -> Semence pastèque | B18: =+'Hypothèse de base'!I7+'Hypothèse de base'!I18 -> 720000 | C18: =B18+(B18*$C$16) -> 763200 | D18: =C18+(C18*$D$16) -> 824256 | E18: =D18+(D18*$E$16) -> 890196.48 | F18: =E18+(E18*$F$16) -> 961412.2
A19: =+'Hypothèse de base'!A8 -> Engrais NPK 50 kg | B19: =+'Hypothèse de base'!I8+'Hypothèse de base'!I19 -> 550000 | C19: =B19+(B19*$C$16) -> 583000 | D19: =C19+(C19*$D$16) -> 629640 | E19: =D19+(D19*$E$16) -> 680011.2 | F19: =E19+(E19*$F$16) -> 734412.1
A20: =+'Hypothèse de base'!A9 -> Intrant Urée 50 kg | B20: =+'Hypothèse de base'!I9+'Hypothèse de base'!I20 -> 230000 | C20: =B20+(B20*$C$16) -> 243800 | D20: =C20+(C20*$D$16) -> 263304 | E20: =D20+(D20*$E$16) -> 284368.32 | F20: =E20+(E20*$F$16) -> 307117.79
A21: =+'Hypothèse de base'!A10 -> Fongicide + insecticide | B21: =+'Hypothèse de base'!I10+'Hypothèse de base'!I21 -> 360000 | C21: =B21+(B21*$C$16) -> 381600 | D21: =C21+(C21*$D$16) -> 412128 | E21: =D21+(D21*$E$16) -> 445098.24 | F21: =E21+(E21*$F$16) -> 480706.1
A22: =+'Hypothèse de base'!A11 -> Fumure organique | B22: =+'Hypothèse de base'!I11+'Hypothèse de base'!I22 -> 60000 | C22: =B22+(B22*$C$16) -> 63600 | D22: =C22+(C22*$D$16) -> 68688 | E22: =D22+(D22*$E$16) -> 74183.04 | F22: =E22+(E22*$F$16) -> 80117.683
A23: =+'Hypothèse de base'!A12 -> 0 | B23: =+'Hypothèse de base'!I12 -> 0 | C23: =B23+(B23*$C$16) -> 0 | D23: =C23+(C23*$D$16) -> 0 | E23: =D23+(D23*$E$16) -> 0 | F23: =E23+(E23*$F$16) -> 0
A24: Total | B24: =SUM(B18:B23) -> 1920000 | C24: =SUM(C18:C23) -> 2035200 | D24: =SUM(D18:D23) -> 2198016 | E24: =SUM(E18:E23) -> 2373857.3 | F24: =SUM(F18:F23) -> 2563765.9
A26: 2.2 Charges de Personnel | B26: 0 | C26: 0.05 | D26: 0 | E26: 0 | F26: =E26 -> 0
A27: Désignations/Années | B27: AN1 | C27: AN2 | D27: AN3 | E27: AN4 | F27: AN5
A28: Frais de personnel | B28: =+'Hypothèse de base'!H38 -> 2100000 | C28: =B28+(B28*$C$26) -> 2205000 | D28: =C28+(C28*$D$26) -> 2205000 | E28: =D28+(D28*$E$26) -> 2205000 | F28: =E28+(E28*$F$26) -> 2205000
C29: =+B29 -> 0 | D29: =+C29*1.05 -> 0 | E29: =+D29 -> 0 | F29: =+E29*1.05 -> 0
A30: Masse salariale | B30: =SUM(B28:B29) -> 2100000 | C30: =SUM(C28:C29) -> 2205000 | D30: =SUM(D28:D29) -> 2205000 | E30: =SUM(E28:E29) -> 2205000 | F30: =SUM(F28:F29) -> 2205000
A32: 2.3 Impôts et taxes
A33: Désignations/Années | B33: AN1 | C33: AN2 | D33: AN3 | E33: AN4 | F33: AN5
A34: Taxes apprentissage | B34: =0.5%*B30 -> 10500 | C34: =0.5%*C30 -> 11025 | D34: =0.5%*D30 -> 11025 | E34: =0.5%*E30 -> 11025 | F34: =0.5%*F30 -> 11025
A35: Contribution forfaitaire | B35: =7.5%*B30 -> 157500 | C35: =7.5%*C30 -> 165375 | D35: =7.5%*D30 -> 165375 | E35: =7.5%*E30 -> 165375 | F35: =7.5%*F30 -> 165375
A36: Taxe de logement | B36: =+B30*1% -> 21000 | C36: =+C30*1% -> 22050 | D36: =+D30*1% -> 22050 | E36: =+E30*1% -> 22050 | F36: =+F30*1% -> 22050
A37: Autres impots et taxes (taxe de voirie, licences, droits d’enregistrement / de timbre, synthétique) | C37: =+B37 -> 0 | D37: =+C37 -> 0 | E37: =+D37 -> 0 | F37: =+E37 -> 0
A38: Total | B38: =SUM(B34:B37) -> 189000 | C38: =SUM(C34:C37) -> 198450 | D38: =SUM(D34:D37) -> 198450 | E38: =SUM(E34:E37) -> 198450 | F38: =SUM(F34:F37) -> 198450
A40: 2.4 Travaux-Fournitures et Services Extérieurs (TFSE)
A41: Désignations/Années | B41: AN1 | C41: AN2 | D41: AN3 | E41: AN4 | F41: AN5
A42: =+'Hypothèse de base'!A91 -> Transports / déplacements | B42: =+'Hypothèse de base'!F91 -> 450000 | C42: =B42+(B42*$C$26) -> 472500 | D42: =C42+(C42*$D$26) -> 472500 | E42: =D42+(D42*$E$26) -> 472500 | F42: =E42+(E42*$F$26) -> 472500
A43: =+'Hypothèse de base'!A92 -> 0 | B43: =+'Hypothèse de base'!F92 -> 0 | C43: =B43+(B43*$C$26) -> 0 | D43: =C43+(C43*$D$26) -> 0 | E43: =D43+(D43*$E$26) -> 0 | F43: =E43+(E43*$F$26) -> 0
A44: =+'Hypothèse de base'!A93 -> 0 | B44: =+'Hypothèse de base'!F93 -> 0 | C44: =B44+(B44*$C$26) -> 0 | D44: =C44+(C44*$D$26) -> 0 | E44: =D44+(D44*$E$26) -> 0 | F44: =E44+(E44*$F$26) -> 0
A45: =+'Hypothèse de base'!A94 -> 0 | B45: =+'Hypothèse de base'!F94 -> 0 | C45: =B45+(B45*$C$26) -> 0 | D45: =C45+(C45*$D$26) -> 0 | E45: =D45+(D45*$E$26) -> 0 | F45: =E45+(E45*$F$26) -> 0
A46: =+'Hypothèse de base'!A95 -> 0 | B46: =+'Hypothèse de base'!F95 -> 0 | C46: =B46+(B46*$C$26) -> 0 | D46: =C46+(C46*$D$26) -> 0 | E46: =D46+(D46*$E$26) -> 0 | F46: =E46+(E46*$F$26) -> 0
A47: =+'Hypothèse de base'!A96 -> 0 | B47: =+'Hypothèse de base'!F96 -> 0 | C47: =B47+(B47*$C$26) -> 0 | D47: =C47+(C47*$D$26) -> 0 | E47: =D47+(D47*$E$26) -> 0 | F47: =E47+(E47*$F$26) -> 0
...

Sheet Echéancier Prêt
A1: Montant du Prêt : | C1: =+'Plan Financement'!C14 -> 3000000 | D1: FCFA
A2: Taux d'intérêt : | C2: =+'Plan Financement'!B20 -> 0.08 | D2: par an soit | E2: =C2/12 -> 0.0066666667 | F2: par mois
A3: TAF : | C3: =+'Plan Financement'!B23 -> 0.17 | D3: par an
A4: Taux d'intérêt appliqué TTC : | C4: =C2*(1+C3) -> 0.0936 | D4: par an
A5: Période de remboursement : | C5: par mois
A6: Période de différé : | C6: =+'Plan Financement'!B21 -> 3 | D6: mois
A7: Durée du prêt : | C7: =+'Plan Financement'!B19 -> 36 | D7: mois
A8: Nombre d'échéance : | C8: =+C7-C6 -> 33
A10: Période | B10: Montant | C10: Intérêts | D10: TAF | E10: Frais Financier | F10: Remboursement | M10: Intérêts | N10: TAF
F11: Principal | G11: Périodicité dégressive | H11: Périodicité linéaire | L11: Périodicité dégressive
A12: 1 | B12: =C1 -> 3000000 | C12: =+IF(M12>=0,M12,0) -> 20000 | D12: =+IF(N12>=0,N12,0) -> 3400 | E12: =+C12+D12 -> 23400 | F12: =+IF(C12>1,J12,0) -> 0 | G12: =+IF(E12>1,L12,0) -> 23400 | H12: =IF(F12<=0,0,$L$50) -> 0 | J12: =+G12-E12 -> 0 | L12: =IF($C$6<>0,E12,($C$1/$C$8)+E12) -> 23400 | M12: =B12*E$2 -> 20000 | N12: =M12*C$3 -> 3400
A13: =A12+1 -> 2 | B13: =B12-F12 -> 3000000 | C13: =+IF(M13>=0,M13,0) -> 20000 | D13: =+IF(N13>=0,N13,0) -> 3400 | E13: =+C13+D13 -> 23400 | F13: =+IF(C13>1,J13,0) -> 0 | G13: =+IF(E13>1,L13,0) -> 23400 | H13: =IF(F13<=0,0,$L$50) -> 0 | J13: =+G13-E13 -> 0 | L13: =IF($C$6>=2,E13,($C$1/$C$8)+E13) -> 23400 | M13: =B13*E$2 -> 20000 | N13: =M13*C$3 -> 3400
A14: =A13+1 -> 3 | B14: =B13-F13 -> 3000000 | C14: =+IF(M14>=0,M14,0) -> 20000 | D14: =+IF(N14>=0,N14,0) -> 3400 | E14: =+C14+D14 -> 23400 | F14: =+IF(C14>1,J14,0) -> 0 | G14: =+IF(E14>1,L14,0) -> 23400 | H14: =IF(F14<=0,0,$L$50) -> 0 | J14: =+G14-E14 -> 0 | L14: =IF($C$6>=3,E14,($C$1/$C$8)+E14) -> 23400 | M14: =B14*E$2 -> 20000 | N14: =M14*C$3 -> 3400
A15: =A14+1 -> 4 | B15: =B14-F14 -> 3000000 | C15: =+IF(M15>=0,M15,0) -> 20000 | D15: =+IF(N15>=0,N15,0) -> 3400 | E15: =+C15+D15 -> 23400 | F15: =+IF(C15>1,J15,0) -> 90909.091 | G15: =+IF(E15>1,L15,0) -> 114309.09 | H15: =IF(F15<=0,0,$L$50) -> 105090.91 | J15: =+G15-E15 -> 90909.091 | L15: =IF($C$6>=4,E15,($C$1/$C$8)+E15) -> 114309.09 | M15: =B15*E$2 -> 20000 | N15: =M15*C$3 -> 3400
A16: =A15+1 -> 5 | B16: =B15-F15 -> 2909090.9 | C16: =+IF(M16>=0,M16,0) -> 19393.939 | D16: =+IF(N16>=0,N16,0) -> 3296.9697 | E16: =+C16+D16 -> 22690.909 | F16: =+IF(C16>1,J16,0) -> 90909.091 | G16: =+IF(E16>1,L16,0) -> 113600 | H16: =IF(F16<=0,0,$L$50) -> 105090.91 | J16: =+G16-E16 -> 90909.091 | L16: =IF($C$6>=5,E16,($C$1/$C$8)+E16) -> 113600 | M16: =B16*E$2 -> 19393.939 | N16: =M16*C$3 -> 3296.9697
A17: =A16+1 -> 6 | B17: =B16-F16 -> 2818181.8 | C17: =+IF(M17>=0,M17,0) -> 18787.879 | D17: =+IF(N17>=0,N17,0) -> 3193.9394 | E17: =+C17+D17 -> 21981.818 | F17: =+IF(C17>1,J17,0) -> 90909.091 | G17: =+IF(E17>1,L17,0) -> 112890.91 | H17: =IF(F17<=0,0,$L$50) -> 105090.91 | J17: =+G17-E17 -> 90909.091 | L17: =IF($C$6>=6,E17,($C$1/$C$8)+E17) -> 112890.91 | M17: =B17*E$2 -> 18787.879 | N17: =M17*C$3 -> 3193.9394
A18: =A17+1 -> 7 | B18: =B17-F17 -> 2727272.7 | C18: =+IF(M18>=0,M18,0) -> 18181.818 | D18: =+IF(N18>=0,N18,0) -> 3090.9091 | E18: =+C18+D18 -> 21272.727 | F18: =+IF(C18>1,J18,0) -> 90909.091 | G18: =+IF(E18>1,L18,0) -> 112181.82 | H18: =IF(F18<=0,0,$L$50) -> 105090.91 | J18: =+G18-E18 -> 90909.091 | L18: =IF($C$6>=7,E18,($C$1/$C$8)+E18) -> 112181.82 | M18: =B18*E$2 -> 18181.818 | N18: =M18*C$3 -> 3090.9091
A19: =A18+1 -> 8 | B19: =B18-F18 -> 2636363.6 | C19: =+IF(M19>=0,M19,0) -> 17575.758 | D19: =+IF(N19>=0,N19,0) -> 2987.8788 | E19: =+C19+D19 -> 20563.636 | F19: =+IF(C19>1,J19,0) -> 90909.091 | G19: =+IF(E19>1,L19,0) -> 111472.73 | H19: =IF(F19<=0,0,$L$50) -> 105090.91 | J19: =+G19-E19 -> 90909.091 | L19: =IF($C$6>=8,E19,($C$1/$C$8)+E19) -> 111472.73 | M19: =B19*E$2 -> 17575.758 | N19: =M19*C$3 -> 2987.8788
A20: =A19+1 -> 9 | B20: =B19-F19 -> 2545454.5 | C20: =+IF(M20>=0,M20,0) -> 16969.697 | D20: =+IF(N20>=0,N20,0) -> 2884.8485 | E20: =+C20+D20 -> 19854.545 | F20: =+IF(C20>1,J20,0) -> 90909.091 | G20: =+IF(E20>1,L20,0) -> 110763.64 | H20: =IF(F20<=0,0,$L$50) -> 105090.91 | J20: =+G20-E20 -> 90909.091 | L20: =IF($C$6>=9,E20,($C$1/$C$8)+E20) -> 110763.64 | M20: =B20*E$2 -> 16969.697 | N20: =M20*C$3 -> 2884.8485
A21: =A20+1 -> 10 | B21: =B20-F20 -> 2454545.5 | C21: =+IF(M21>=0,M21,0) -> 16363.636 | D21: =+IF(N21>=0,N21,0) -> 2781.8182 | E21: =+C21+D21 -> 19145.455 | F21: =+IF(C21>1,J21,0) -> 90909.091 | G21: =+IF(E21>1,L21,0) -> 110054.55 | H21: =IF(F21<=0,0,$L$50) -> 105090.91 | J21: =+G21-E21 -> 90909.091 | L21: =IF($C$6>=10,E21,($C$1/$C$8)+E21) -> 110054.55 | M21: =B21*E$2 -> 16363.636 | N21: =M21*C$3 -> 2781.8182
A22: =A21+1 -> 11 | B22: =B21-F21 -> 2363636.4 | C22: =+IF(M22>=0,M22,0) -> 15757.576 | D22: =+IF(N22>=0,N22,0) -> 2678.7879 | E22: =+C22+D22 -> 18436.364 | F22: =+IF(C22>1,J22,0) -> 90909.091 | G22: =+IF(E22>1,L22,0) -> 109345.45 | H22: =IF(F22<=0,0,$L$50) -> 105090.91 | J22: =+G22-E22 -> 90909.091 | L22: =IF($C$6>=11,E22,($C$1/$C$8)+E22) -> 109345.45 | M22: =B22*E$2 -> 15757.576 | N22: =M22*C$3 -> 2678.7879
A23: =A22+1 -> 12 | B23: =B22-F22 -> 2272727.3 | C23: =+IF(M23>=0,M23,0) -> 15151.515 | D23: =+IF(N23>=0,N23,0) -> 2575.7576 | E23: =+C23+D23 -> 17727.273 | F23: =+IF(C23>1,J23,0) -> 90909.091 | G23: =+IF(E23>1,L23,0) -> 108636.36 | H23: =IF(F23<=0,0,$L$50) -> 105090.91 | J23: =+G23-E23 -> 90909.091 | L23: =IF($C$6>=12,E23,($C$1/$C$8)+E23) -> 108636.36 | M23: =B23*E$2 -> 15151.515 | N23: =M23*C$3 -> 2575.7576
A24: =A23+1 -> 13 | B24: =B23-F23 -> 2181818.2 | C24: =+IF(M24>=0,M24,0) -> 14545.455 | D24: =+IF(N24>=0,N24,0) -> 2472.7273 | E24: =+C24+D24 -> 17018.182 | F24: =+IF(C24>1,J24,0) -> 90909.091 | G24: =+IF(E24>1,L24,0) -> 107927.27 | H24: =IF(F24<=0,0,$L$50) -> 105090.91 | J24: =+G24-E24 -> 90909.091 | L24: =IF($C$6>=13,E24,($C$1/$C$8)+E24) -> 107927.27 | M24: =B24*E$2 -> 14545.455 | N24: =M24*C$3 -> 2472.7273
A25: =A24+1 -> 14 | B25: =B24-F24 -> 2090909.1 | C25: =+IF(M25>=0,M25,0) -> 13939.394 | D25: =+IF(N25>=0,N25,0) -> 2369.697 | E25: =+C25+D25 -> 16309.091 | F25: =+IF(C25>1,J25,0) -> 90909.091 | G25: =+IF(E25>1,L25,0) -> 107218.18 | H25: =IF(F25<=0,0,$L$50) -> 105090.91 | J25: =+G25-E25 -> 90909.091 | L25: =IF($C$6>=14,E25,($C$1/$C$8)+E25) -> 107218.18 | M25: =B25*E$2 -> 13939.394 | N25: =M25*C$3 -> 2369.697
A26: =A25+1 -> 15 | B26: =B25-F25 -> 2000000 | C26: =+IF(M26>=0,M26,0) -> 13333.333 | D26: =+IF(N26>=0,N26,0) -> 2266.6667 | E26: =+C26+D26 -> 15600 | F26: =+IF(C26>1,J26,0) -> 90909.091 | G26: =+IF(E26>1,L26,0) -> 106509.09 | H26: =IF(F26<=0,0,$L$50) -> 105090.91 | J26: =+G26-E26 -> 90909.091 | L26: =IF($C$6>=15,E26,($C$1/$C$8)+E26) -> 106509.09 | M26: =B26*E$2 -> 13333.333 | N26: =M26*C$3 -> 2266.6667
A27: =A26+1 -> 16 | B27: =B26-F26 -> 1909090.9 | C27: =+IF(M27>=0,M27,0) -> 12727.273 | D27: =+IF(N27>=0,N27,0) -> 2163.6364 | E27: =+C27+D27 -> 14890.909 | F27: =+IF(C27>1,J27,0) -> 90909.091 | G27: =+IF(E27>1,L27,0) -> 105800 | H27: =IF(F27<=0,0,$L$50) -> 105090.91 | J27: =+G27-E27 -> 90909.091 | L27: =IF($C$6>=16,E27,($C$1/$C$8)+E27) -> 105800 | M27: =B27*E$2 -> 12727.273 | N27: =M27*C$3 -> 2163.6364
A28: =A27+1 -> 17 | B28: =B27-F27 -> 1818181.8 | C28: =+IF(M28>=0,M28,0) -> 12121.212 | D28: =+IF(N28>=0,N28,0) -> 2060.6061 | E28: =+C28+D28 -> 14181.818 | F28: =+IF(C28>1,J28,0) -> 90909.091 | G28: =+IF(E28>1,L28,0) -> 105090.91 | H28: =IF(F28<=0,0,$L$50) -> 105090.91 | J28: =+G28-E28 -> 90909.091 | L28: =IF($C$6>=17,E28,($C$1/$C$8)+E28) -> 105090.91 | M28: =B28*E$2 -> 12121.212 | N28: =M28*C$3 -> 2060.6061
A29: =A28+1 -> 18 | B29: =B28-F28 -> 1727272.7 | C29: =+IF(M29>=0,M29,0) -> 11515.152 | D29: =+IF(N29>=0,N29,0) -> 1957.5758 | E29: =+C29+D29 -> 13472.727 | F29: =+IF(C29>1,J29,0) -> 90909.091 | G29: =+IF(E29>1,L29,0) -> 104381.82 | H29: =IF(F29<=0,0,$L$50) -> 105090.91 | J29: =+G29-E29 -> 90909.091 | L29: =IF($C$6>=18,E29,($C$1/$C$8)+E29) -> 104381.82 | M29: =B29*E$2 -> 11515.152 | N29: =M29*C$3 -> 1957.5758
A30: =A29+1 -> 19 | B30: =B29-F29 -> 1636363.6 | C30: =+IF(M30>=0,M30,0) -> 10909.091 | D30: =+IF(N30>=0,N30,0) -> 1854.5455 | E30: =+C30+D30 -> 12763.636 | F30: =+IF(C30>1,J30,0) -> 90909.091 | G30: =+IF(E30>1,L30,0) -> 103672.73 | H30: =IF(F30<=0,0,$L$50) -> 105090.91 | J30: =+G30-E30 -> 90909.091 | L30: =IF($C$6>=19,E30,($C$1/$C$8)+E30) -> 103672.73 | M30: =B30*E$2 -> 10909.091 | N30: =M30*C$3 -> 1854.5455
A31: =A30+1 -> 20 | B31: =B30-F30 -> 1545454.5 | C31: =+IF(M31>=0,M31,0) -> 10303.03 | D31: =+IF(N31>=0,N31,0) -> 1751.5152 | E31: =+C31+D31 -> 12054.545 | F31: =+IF(C31>1,J31,0) -> 90909.091 | G31: =+IF(E31>1,L31,0) -> 102963.64 | H31: =IF(F31<=0,0,$L$50) -> 105090.91 | J31: =+G31-E31 -> 90909.091 | L31: =IF($C$6>=20,E31,($C$1/$C$8)+E31) -> 102963.64 | M31: =B31*E$2 -> 10303.03 | N31: =M31*C$3 -> 1751.5152
A32: =A31+1 -> 21 | B32: =B31-F31 -> 1454545.5 | C32: =+IF(M32>=0,M32,0) -> 9696.9697 | D32: =+IF(N32>=0,N32,0) -> 1648.4848 | E32: =+C32+D32 -> 11345.455 | F32: =+IF(C32>1,J32,0) -> 90909.091 | G32: =+IF(E32>1,L32,0) -> 102254.55 | H32: =IF(F32<=0,0,$L$50) -> 105090.91 | J32: =+G32-E32 -> 90909.091 | L32: =IF($C$6>=21,E32,($C$1/$C$8)+E32) -> 102254.55 | M32: =B32*E$2 -> 9696.9697 | N32: =M32*C$3 -> 1648.4848
A33: =A32+1 -> 22 | B33: =B32-F32 -> 1363636.4 | C33: =+IF(M33>=0,M33,0) -> 9090.9091 | D33: =+IF(N33>=0,N33,0) -> 1545.4545 | E33: =+C33+D33 -> 10636.364 | F33: =+IF(C33>1,J33,0) -> 90909.091 | G33: =+IF(E33>1,L33,0) -> 101545.45 | H33: =IF(F33<=0,0,$L$50) -> 105090.91 | J33: =+G33-E33 -> 90909.091 | L33: =IF($C$6>=22,E33,($C$1/$C$8)+E33) -> 101545.45 | M33: =B33*E$2 -> 9090.9091 | N33: =M33*C$3 -> 1545.4545
A34: =A33+1 -> 23 | B34: =B33-F33 -> 1272727.3 | C34: =+IF(M34>=0,M34,0) -> 8484.8485 | D34: =+IF(N34>=0,N34,0) -> 1442.4242 | E34: =+C34+D34 -> 9927.2727 | F34: =+IF(C34>1,J34,0) -> 90909.091 | G34: =+IF(E34>1,L34,0) -> 100836.36 | H34: =IF(F34<=0,0,$L$50) -> 105090.91 | J34: =+G34-E34 -> 90909.091 | L34: =IF($C$6>=23,E34,($C$1/$C$8)+E34) -> 100836.36 | M34: =B34*E$2 -> 8484.8485 | N34: =M34*C$3 -> 1442.4242
A35: =A34+1 -> 24 | B35: =B34-F34 -> 1181818.2 | C35: =+IF(M35>=0,M35,0) -> 7878.7879 | D35: =+IF(N35>=0,N35,0) -> 1339.3939 | E35: =+C35+D35 -> 9218.1818 | F35: =+IF(C35>1,J35,0) -> 90909.091 | G35: =+IF(E35>1,L35,0) -> 100127.27 | H35: =IF(F35<=0,0,$L$50) -> 105090.91 | J35: =+G35-E35 -> 90909.091 | L35: =IF($C$6>=24,E35,($C$1/$C$8)+E35) -> 100127.27 | M35: =B35*E$2 -> 7878.7879 | N35: =M35*C$3 -> 1339.3939
A36: =A35+1 -> 25 | B36: =B35-F35 -> 1090909.1 | C36: =+IF(M36>=0,M36,0) -> 7272.7273 | D36: =+IF(N36>=0,N36,0) -> 1236.3636 | E36: =+C36+D36 -> 8509.0909 | F36: =+IF(C36>1,J36,0) -> 90909.091 | G36: =+IF(E36>1,L36,0) -> 99418.182 | H36: =IF(F36<=0,0,$L$50) -> 105090.91 | J36: =+G36-E36 -> 90909.091 | L36: =IF($C$6>=25,E36,($C$1/$C$8)+E36) -> 99418.182 | M36: =B36*E$2 -> 7272.7273 | N36: =M36*C$3 -> 1236.3636
A37: =A36+1 -> 26 | B37: =B36-F36 -> 1000000 | C37: =+IF(M37>=0,M37,0) -> 6666.6667 | D37: =+IF(N37>=0,N37,0) -> 1133.3333 | E37: =+C37+D37 -> 7800 | F37: =+IF(C37>1,J37,0) -> 90909.091 | G37: =+IF(E37>1,L37,0) -> 98709.091 | H37: =IF(F37<=0,0,$L$50) -> 105090.91 | J37: =+G37-E37 -> 90909.091 | L37: =IF($C$6>=26,E37,($C$1/$C$8)+E37) -> 98709.091 | M37: =B37*E$2 -> 6666.6667 | N37: =M37*C$3 -> 1133.3333
A38: =A37+1 -> 27 | B38: =B37-F37 -> 909090.91 | C38: =+IF(M38>=0,M38,0) -> 6060.6061 | D38: =+IF(N38>=0,N38,0) -> 1030.303 | E38: =+C38+D38 -> 7090.9091 | F38: =+IF(C38>1,J38,0) -> 90909.091 | G38: =+IF(E38>1,L38,0) -> 98000 | H38: =IF(F38<=0,0,$L$50) -> 105090.91 | J38: =+G38-E38 -> 90909.091 | L38: =IF($C$6>=27,E38,($C$1/$C$8)+E38) -> 98000 | M38: =B38*E$2 -> 6060.6061 | N38: =M38*C$3 -> 1030.303
A39: =A38+1 -> 28 | B39: =B38-F38 -> 818181.82 | C39: =+IF(M39>=0,M39,0) -> 5454.5455 | D39: =+IF(N39>=0,N39,0) -> 927.27273 | E39: =+C39+D39 -> 6381.8182 | F39: =+IF(C39>1,J39,0) -> 90909.091 | G39: =+IF(E39>1,L39,0) -> 97290.909 | H39: =IF(F39<=0,0,$L$50) -> 105090.91 | J39: =+G39-E39 -> 90909.091 | L39: =IF($C$6>=28,E39,($C$1/$C$8)+E39) -> 97290.909 | M39: =B39*E$2 -> 5454.5455 | N39: =M39*C$3 -> 927.27273
A40: =A39+1 -> 29 | B40: =B39-F39 -> 727272.73 | C40: =+IF(M40>=0,M40,0) -> 4848.4848 | D40: =+IF(N40>=0,N40,0) -> 824.24242 | E40: =+C40+D40 -> 5672.7273 | F40: =+IF(C40>1,J40,0) -> 90909.091 | G40: =+IF(E40>1,L40,0) -> 96581.818 | H40: =IF(F40<=0,0,$L$50) -> 105090.91 | J40: =+G40-E40 -> 90909.091 | L40: =IF($C$6>=29,E40,($C$1/$C$8)+E40) -> 96581.818 | M40: =B40*E$2 -> 4848.4848 | N40: =M40*C$3 -> 824.24242
A41: =A40+1 -> 30 | B41: =B40-F40 -> 636363.64 | C41: =+IF(M41>=0,M41,0) -> 4242.4242 | D41: =+IF(N41>=0,N41,0) -> 721.21212 | E41: =+C41+D41 -> 4963.6364 | F41: =+IF(C41>1,J41,0) -> 90909.091 | G41: =+IF(E41>1,L41,0) -> 95872.727 | H41: =IF(F41<=0,0,$L$50) -> 105090.91 | J41: =+G41-E41 -> 90909.091 | L41: =IF($C$6>=30,E41,($C$1/$C$8)+E41) -> 95872.727 | M41: =B41*E$2 -> 4242.4242 | N41: =M41*C$3 -> 721.21212
...

Sheet Compte d'exploitation
A2: D. COMPTE D'EXPLOITATION PREVISIONNEL (FCFA)
A4: Désignations/Années | B4: AN1 | C4: AN2 | D4: AN3 | E4: AN4 | F4: AN5
A5: 1. Recettes prévisionnelles
A6: Total recettes | B6: ='Eléments du compte d''exploitati'!B12 -> 7400000 | C6: ='Eléments du compte d''exploitati'!C12 -> 7548000 | D6: ='Eléments du compte d''exploitati'!D12 -> 7698960 | E6: ='Eléments du compte d''exploitati'!E12 -> 7852939.2 | F6: ='Eléments du compte d''exploitati'!F12 -> 8009998
A8: 2. Charges d'exploitation
A9: Achats (matières premières et autres achats) | B9: =+'Eléments du compte d''exploitati'!B24 -> 1920000 | C9: =+'Eléments du compte d''exploitati'!C24 -> 2035200 | D9: =+'Eléments du compte d''exploitati'!D24 -> 2198016 | E9: =+'Eléments du compte d''exploitati'!E24 -> 2373857.3 | F9: =+'Eléments du compte d''exploitati'!F24 -> 2563765.9
A10: Charges de Personnel | B10: =+'Eléments du compte d''exploitati'!B30 -> 2100000 | C10: =+'Eléments du compte d''exploitati'!C30 -> 2205000 | D10: =+'Eléments du compte d''exploitati'!D30 -> 2205000 | E10: =+'Eléments du compte d''exploitati'!E30 -> 2205000 | F10: =+'Eléments du compte d''exploitati'!F30 -> 2205000
A11: Travaux-Fournitures et Services Extérieurs (TFSE) | B11: =+'Eléments du compte d''exploitati'!B49 -> 450000 | C11: =+'Eléments du compte d''exploitati'!C49 -> 472500 | D11: =+'Eléments du compte d''exploitati'!D49 -> 472500 | E11: =+'Eléments du compte d''exploitati'!E49 -> 472500 | F11: =+'Eléments du compte d''exploitati'!F49 -> 472500
A12: Autres charges | B12: =+'Eléments du compte d''exploitati'!B62 -> 0 | C12: =+'Eléments du compte d''exploitati'!C62 -> 0 | D12: =+'Eléments du compte d''exploitati'!D62 -> 0 | E12: =+'Eléments du compte d''exploitati'!E62 -> 0 | F12: =+'Eléments du compte d''exploitati'!F62 -> 0
A13: Frais financiers et charges assimilées | B13: =+SUM('Echéancier Prêt'!E12:E23) -> 255272.73 | C13: =+SUM('Echéancier Prêt'!E24:E35) -> 157418.18 | D13: =+SUM('Echéancier Prêt'!E36:E47) -> 55309.091 | E13: 0 | F13: 0
A14: Dotations aux amortissements | B14: ='Eléments du compte d''exploitati'!D92 -> 968916.67 | C14: ='Eléments du compte d''exploitati'!E92 -> 953916.67 | D14: ='Eléments du compte d''exploitati'!F92 -> 953916.67 | E14: ='Eléments du compte d''exploitati'!G92 -> 947250 | F14: ='Eléments du compte d''exploitati'!H92 -> 176000
A15: Total charges | B15: =SUM(B9:B14) -> 5694189.4 | C15: =SUM(C9:C14) -> 5824034.8 | D15: =SUM(D9:D14) -> 5884741.8 | E15: =SUM(E9:E14) -> 5998607.3 | F15: =SUM(F9:F14) -> 5417265.9
A17: Résultats bruts | B17: =B6-B15 -> 1705810.6 | C17: =C6-C15 -> 1723965.2 | D17: =D6-D15 -> 1814218.2 | E17: =E6-E15 -> 1854331.9 | F17: =F6-F15 -> 2592732.1
A18: BIC | B18: =30%*B17*0 -> 0 | C18: =30%*C17*0 -> 0 | D18: =30%*D17*0 -> 0 | E18: =30%*E17*0 -> 0 | F18: =30%*F17*0 -> 0
A19: Impôts et taxes | B19: =+'Eléments du compte d''exploitati'!B38 -> 189000 | C19: =+'Eléments du compte d''exploitati'!C38 -> 198450 | D19: =+'Eléments du compte d''exploitati'!D38 -> 198450 | E19: =+'Eléments du compte d''exploitati'!E38 -> 198450 | F19: =+'Eléments du compte d''exploitati'!F38 -> 198450
A20: Résultats nets | B20: =+B17-B18-B19 -> 1516810.6 | C20: =+C17-C18-C19 -> 1525515.2 | D20: =+D17-D18-D19 -> 1615768.2 | E20: =+E17-E18-E19 -> 1655881.9 | F20: =+F17-F18-F19 -> 2394282.1
I21: 0
A22: CAF | B22: =B20+B14 -> 2485727.3 | C22: =C20+C14 -> 2479431.8 | D22: =D20+D14 -> 2569684.9 | E22: =E20+E14 -> 2603131.9 | F22: =F20+F14 -> 2570282.1
A23: CAF CUMULEE | B23: =+B22 -> 2485727.3 | C23: =C22+B23 -> 4965159.1 | D23: =D22+C23 -> 7534844 | E23: =E22+D23 -> 10137976 | F23: =F22+E23 -> 12708258

Sheet Compte de tresorerie
A2: E. COMPTE DE TRESORERIE (FCFA)
A4: Désignations/Années | B4: AN0 | C4: AN1 | D4: AN2 | E4: AN3 | F4: AN4 | G4: AN5
A5: SOURCES DE FONDS
A6: Apport personnel | B6: ='Plan Financement'!C7 -> 500000
A7: Crédit | B7: ='Plan Financement'!C14 -> 3000000
A8: Contribution (Primes) FACEJ | B8: =SUM('Plan Financement'!C11:C12) -> 0
A9: Subvention (Projet Vert/verdissement) | B9: ='Plan Financement'!C13 -> 1500000
A10: Dotation aux Amortissements | C10: ='Compte d''exploitation'!B14 -> 968916.67 | D10: ='Compte d''exploitation'!C14 -> 953916.67 | E10: ='Compte d''exploitation'!D14 -> 953916.67 | F10: ='Compte d''exploitation'!E14 -> 947250 | G10: ='Compte d''exploitation'!F14 -> 176000
A11: Résultats nets | C11: =+'Compte d''exploitation'!B20 -> 1516810.6 | D11: =+'Compte d''exploitation'!C20 -> 1525515.2 | E11: =+'Compte d''exploitation'!D20 -> 1615768.2 | F11: =+'Compte d''exploitation'!E20 -> 1655881.9 | G11: =+'Compte d''exploitation'!F20 -> 2394282.1
A12: Total RESSOURCES | B12: =SUM(B6:B11) -> 5000000 | C12: =SUM(C6:C11) -> 2485727.3 | D12: =SUM(D6:D11) -> 2479431.8 | E12: =SUM(E6:E11) -> 2569684.9 | F12: =SUM(F6:F11) -> 2603131.9 | G12: =SUM(G6:G11) -> 2570282.1
A13: EMPLOIS DE FONDS
A14: Frais d'établissements | B14: =+'Coût du projet'!C4 -> 15000
A15: Frais d'investissement | B15: =+'Coût du projet'!C11 -> 3985000
A16: BFR | B16: =+'Coût du projet'!C40 -> 1000000
A17: Remboursement de CREDIT MOYEN TERME | C17: =+SUM('Echéancier Prêt'!F12:F23) -> 818181.82 | D17: =+SUM('Echéancier Prêt'!F24:F35) -> 1090909.1 | E17: =+SUM('Echéancier Prêt'!F36:F47) -> 1090909.1 | F17: 0 | G17: 0
A18: Total EMPLOIS | B18: =SUM(B14:B17) -> 5000000 | C18: =SUM(C14:C17) -> 818181.82 | D18: =SUM(D14:D17) -> 1090909.1 | E18: =SUM(E14:E17) -> 1090909.1 | F18: =SUM(F14:F17) -> 0 | G18: =SUM(G14:G17) -> 0
A20: TRESORERIE DEGAGEE | B20: =+B12-B18 -> 0 | C20: =+C12-C18 -> 1667545.5 | D20: =+D12-D18 -> 1388522.7 | E20: =+E12-E18 -> 1478775.8 | F20: =+F12-F18 -> 2603131.9 | G20: =+G12-G18 -> 2570282.1
A21: TRESORERIE CUMULEE | B21: =+B20 -> 0 | C21: =B21+C20 -> 1667545.5 | D21: =C21+D20 -> 3056068.2 | E21: =D21+E20 -> 4534844 | F21: =E21+F20 -> 7137975.9 | G21: =F21+G20 -> 9708258
A23: ELEMENTS DU CALCUL DES RATIOS
A24: =+'Plan Financement'!B20 -> 0.08
A25: =-B18 -> -5000000 | B25: =+'Compte d''exploitation'!B22 -> 2485727.3 | C25: =+'Compte d''exploitation'!C22 -> 2479431.8 | D25: =+'Compte d''exploitation'!D22 -> 2569684.9 | E25: =+'Compte d''exploitation'!E22 -> 2603131.9 | F25: =+'Compte d''exploitation'!F22 -> 2570282.1 | J25: =B18/(F25*A24) -> 24.316397
C27: TRI (sur CAF, hors financement) | D27: =IRR(A25:F25) -> 0.41553744 | E27: Sur 5 ans
C29: VAN (sur CAF, hors financement) | D29: =A25+NPV(A24,B25:F25) -> 5129881.7 | E29: Sur 5 ans
A31: Calcul du délai de recuperation des capitaux investis
J32: =+J30*A24 -> 0
B33: AN 1 | C33: AN 2 | D33: AN 3 | E33: AN 4 | F33: AN 5
A34: CAF annuelle (autofinancement dégagé) | B34: =+'Compte d''exploitation'!B22 -> 2485727.3 | C34: =+'Compte d''exploitation'!C22 -> 2479431.8 | D34: =+'Compte d''exploitation'!D22 -> 2569684.9 | E34: =+'Compte d''exploitation'!E22 -> 2603131.9 | F34: =+'Compte d''exploitation'!F22 -> 2570282.1
A35: CAF cumulée | B35: =+B34 -> 2485727.3 | C35: =+C34+B35 -> 4965159.1 | D35: =+D34+C35 -> 7534844 | E35: =+E34+D35 -> 10137976 | F35: =+F34+E35 -> 12708258
A37: CALCUL DU DELAI DE RECUPERATION (base CAF, corrige)
A38: Nombre d'années pleines non couvertes (n) | B38: =IF(B35>=$B$18,0,IF(C35>=$B$18,1,IF(D35>=$B$18,2,IF(E35>=$B$18,3,IF(F35>=$B$18,4,5))))) -> 2
A39: CAF cumulée à la fin de l'année n | B39: =CHOOSE(B38+1,0,B35,C35,D35,E35,F35) -> 4965159.1
A40: CAF de l'année n+1 | B40: =CHOOSE(B38+1,B34,C34,D34,E34,F34,F34) -> 2569684.9 | E40: =INT(B41)&" ans "&INT((B41-INT(B41))*12)&" mois "&INT((((B41-INT(B41))*12)-INT((B41-INT(B41))*12))*30) & " jours " -> 2 ans 0 mois 4 jours
A41: Délai de récupération (années décimales) | B41: =B38+IF(B40=0,0,(B18-B39)/B40) -> 2.0135584 | C41: Periode de recuperation
A42: Délai de récupération - SANS actualisation | B42: =IF(ROUND(MOD(B41,1)*12,0)=12,(INT(B41)+1)&" an(s) et 0 mois",INT(B41)&" an(s) et "&ROUND(MOD(B41,1)*12,0)&" mois") -> 2 an(s) et 0 mois | C42: (sans actualisation)
A44: CAF actualisée par année (taux = A24) | B44: =+B17-D36 -> 0
A45: CAF actualisée | B45: =B34/(1+$A$24)^1 -> 2301599.3 | C45: =C34/(1+$A$24)^2 -> 2125713.2 | D45: =D34/(1+$A$24)^3 -> 2039898.7 | E45: =E34/(1+$A$24)^4 -> 1913379.7 | F45: =F34/(1+$A$24)^5 -> 1749290.8
A46: Cumul CAF actualisée | B46: =B45 -> 2301599.3 | C46: =C45+B46 -> 4427312.5 | D46: =D45+C46 -> 6467211.2 | E46: =E45+D46 -> 8380590.9 | F46: =F45+E46 -> 10129882
A47: Nombre d'années pleines non couvertes (actualisé) | B47: =IF(B46>=$B$18,0,IF(C46>=$B$18,1,IF(D46>=$B$18,2,IF(E46>=$B$18,3,IF(F46>=$B$18,4,5))))) -> 2 | C47: (sans actualisation)
A48: Cumul CAF actualisée à la fin de l'année n | B48: =CHOOSE(B47+1,0,B46,C46,D46,E46,F46) -> 4427312.5
A49: CAF actualisée de l'année n+1 | B49: =CHOOSE(B47+1,B45,C45,D45,E45,F45,F45) -> 2039898.7
...

Sheet Bilan
A2: F. BILAN D'OUVERTURE (FCFA)
A4: BILAN DE DEMARRAGE TOUT TYPE PROJET
A6: ACTIF | B6: MONTANT | C6: PASSIF | D6: MONTANT
A7: ACTIF IMMOBILISE | C7: CAPITAUX PROPRES ET RESSOURCES ASSIMILEES
A8: Immobilisations incorporelles | C8: Capitaux Propres (a)+(b) | D8: =+D9+D10 -> 500000
A9: =+'Coût du projet'!A5 -> Frais d'étude / développement | B9: =+'Coût du projet'!B5 -> 0 | C9: Apport en Nature (a) | D9: =+B32 -> 0
A10: =+'Coût du projet'!A6 -> Frais de publicité et de lancement | B10: =+'Coût du projet'!B6 -> 0 | C10: Apport en Espéces (b) | D10: =+'Plan Financement'!C8 -> 500000
A11: =+'Coût du projet'!A7 -> Frais de constitution | B11: =+'Coût du projet'!B7 -> 15000 | C11: Résultat net de l'exercice (bénéfice + ou perte -)
A12: =+'Coût du projet'!A8 -> Frais d'hypothèque | B12: =+'Coût du projet'!B8 -> 0 | C12: Autres capitaux propres
A13: =+'Coût du projet'!A9 -> Frais de nantissement | B13: =+'Coût du projet'!B9 -> 0 | C13: Subventions d'investissement | D13: =+'Compte de tresorerie'!B8+'Compte de tresorerie'!B9 -> 1500000
A14: Immobilisations corporelles
A15: =+'Coût du projet'!A13 -> 0 | B15: =+'Coût du projet'!B13 -> 0
A16: =+'Coût du projet'!A14 -> 0 | B16: =+'Coût du projet'!B14 -> 0 | C16: TOTAL CAPITAUX PROPRES (I) | D16: =+D13+D11+D8 -> 2000000
A17: =+'Coût du projet'!A25 -> Puits à grand diamètre | B17: =+'Coût du projet'!B25 -> 980000
A18: =+'Coût du projet'!A20 -> Aménagement préparatoire | B18: =+'Coût du projet'!B20 -> 45000 | C18: DETTES FINANCIERES ET RESSOURCES ASSIMILEES
A19: =+'Coût du projet'!A21 -> Formation des billons | B19: =+'Coût du projet'!B21 -> 60000 | C19: Emprunts | D19: =+'Plan Financement'!C14 -> 3000000
A20: =+'Coût du projet'!A22 -> Système goutte-à-goutte | B20: =+'Coût du projet'!B22 -> 750000 | C20: Dettes de crédit-bail et contrats assimilés
A21: =+'Coût du projet'!A23 -> Clôture en grillage 0,75 ha | B21: =+'Coût du projet'!B23 -> 1000000 | C21: Dettes financières diverses
A22: =+'Coût du projet'!A24 -> Bassin 40 m³ | B22: =+'Coût du projet'!B24 -> 250000 | C22: TOTAL DES DETTES FINANCIERES (II) | D22: =SUM(D17:D21) -> 3000000
A23: =+'Coût du projet'!A29 -> Balance | B23: =+'Coût du projet'!B29 -> 20000
A24: =+'Coût du projet'!A30 -> 0 | B24: =+'Coût du projet'!B30 -> 0 | C24: TOTAL DES RESSOURCES STABLES ( I + II) | D24: =D16+D22 -> 5000000
A25: =+'Coût du projet'!A32 -> 0 | B25: =+'Coût du projet'!B32 -> 0
A26: =+'Coût du projet'!A33 -> 0 | B26: =+'Coût du projet'!B33 -> 0
A27: =+'Coût du projet'!A35 -> Paillage en plastique | B27: =+'Coût du projet'!B35 -> 400000
A28: =+'Coût du projet'!A36 -> Pulvérisateurs | B28: =+'Coût du projet'!B36 -> 75000
A29: =+'Coût du projet'!A37 -> Brouettes + Houes | B29: =+'Coût du projet'!B37 -> 60000
A30: =+'Coût du projet'!A38 -> P 17 (2000 m) | B30: =+'Coût du projet'!B38 -> 300000
A31: =+'Coût du projet'!A39 -> Outils divers (dabas, pioches, pelles) | B31: =+'Coût du projet'!B39 -> 45000
A32: Anciens équipements | B32: 0
A33: TOTAL ACTIF IMMOBILISE (I) | B33: =SUM(B7:B32) -> 4000000
A34: ACTIF CIRCULANT | C34: PASSIF CIRCULANT
A35: Stocks | C35: Clients, avances reçues
A36: Marchandises | C36: Fournisseurs
A37: Matières premières et autres approvisionnements | B37: =+'Coût du projet'!B41+'Coût du projet'!B42 -> 480000 | C37: Dettes fiscales
A38: En-cours | C38: Dettes sociales
A39: Produits fabriqués | C39: Autres dettes
A40: Créances et emplois assimilés | C40: TOTAL PASSIF CIRCULANT (III) | D40: =SUM(D34:D39) -> 0
A41: Fournisseurs, avances versées
A42: Clients | C42: TRESORERIE - PASSIF
A43: Autres créances | C43: Banques, crédits de trésorerie
...

Sheet Ratios d'analyse
A2: G. RATIOS D'ANALYSE ECONOMIQUE ET FINANCIERE (FCFA)
A4: 1. Le taux de valeur ajoutée
A5: Désignations/Années | B5: AN1 | C5: AN2 | D5: AN3
A6: Frais de personnel | B6: =+'Compte d''exploitation'!B10 -> 2100000 | C6: =+'Compte d''exploitation'!C10 -> 2205000 | D6: =+'Compte d''exploitation'!D10 -> 2205000
A7: Impôts et taxes (non inclus dans la VA) | B7: =+'Compte d''exploitation'!B19 -> 189000 | C7: =+'Compte d''exploitation'!C19 -> 198450 | D7: =+'Compte d''exploitation'!D19 -> 198450
A8: Dotations aux amortissements | B8: =+'Compte d''exploitation'!B14 -> 968916.67 | C8: =+'Compte d''exploitation'!C14 -> 953916.67 | D8: =+'Compte d''exploitation'!D14 -> 953916.67
A9: Frais financiers | B9: =+'Compte d''exploitation'!B13 -> 255272.73 | C9: =+'Compte d''exploitation'!C13 -> 157418.18 | D9: =+'Compte d''exploitation'!D13 -> 55309.091
A10: Resultats bruts | B10: =+'Compte d''exploitation'!B17 -> 1705810.6 | C10: =+'Compte d''exploitation'!C17 -> 1723965.2 | D10: =+'Compte d''exploitation'!D17 -> 1814218.2
A11: Total VA | B11: =+B6+B8+B9+B10 -> 5030000 | C11: =+C6+C8+C9+C10 -> 5040300 | D11: =+D6+D8+D9+D10 -> 5028444
A13: Chiffre d'affaires | B13: =+'Compte d''exploitation'!B6 -> 7400000 | C13: =+'Compte d''exploitation'!C6 -> 7548000 | D13: =+'Compte d''exploitation'!D6 -> 7698960
A15: Taux de VA (%) | B15: =+(B11/B13) -> 0.67972973 | C15: =+(C11/C13) -> 0.6677663 | D15: =+(D11/D13) -> 0.65313289 | I15: 0
A17: Taux moyen de la Valeur Ajoutée | C17: =+AVERAGE(B15:D15) -> 0.66687631
A19: 2. Le seuil de rentabilité
A20: Désignation | B20: Charges fixes | C20: Charges variables
A21: Achats | C21: =+'Compte d''exploitation'!D9 -> 2198016
A22: Frais de Personnel | B22: =+'Compte d''exploitation'!D10 -> 2205000
A23: Impôts et taxes | B23: =+'Compte d''exploitation'!D19 -> 198450
A24: Travaux-Fournitures et Services Extérieurs (TFSE) | C24: =+'Compte d''exploitation'!D11 -> 472500 | J24: 0
A25: =+'Compte d''exploitation'!A12 -> Autres charges | C25: =+'Compte d''exploitation'!D12 -> 0 | J25: 0
A26: Frais financiers et services de la dette | B26: =+'Compte d''exploitation'!D13 -> 55309.091
A27: Dotations aux amortissements | B27: =+'Compte d''exploitation'!D14 -> 953916.67
A28: Total | B28: =+SUM(B21:B27) -> 3412675.8 | C28: =+SUM(C21:C27) -> 2670516
A29: 2. Le Seuil de rentabilité (année 3) | B29: =+(B28/(D13-C28)) -> 0.67867431 | C29: % DU CA
A30: Seuil de rentabilité (année 1) | B30: =+(('Compte d''exploitation'!B10+'Compte d''exploitation'!B19+'Compte d''exploitation'!B13+'Compte d''exploitation'!B14)/('Compte d''exploitation'!B6-('Compte d''exploitation'!B9+'Compte d''exploitation'!B11+'Compte d''exploitation'!B12))) -> 0.6984472 | C30: % DU CA
A31: 3. Le taux de rentabilité interne (TRI) | B31: =+'Compte de tresorerie'!D27 -> 0.41553744
A33: 4. La valeur actuelle nette (VAN) | B33: =+'Compte de tresorerie'!D29 -> 5129881.7 | C33: F.CFA
A35: 5. Délais de récupération (sans actualisation, avec actualisation)
A36: Sans actualisation | C36: =+'Compte de tresorerie'!B42 -> 2 an(s) et 0 mois
A37: Avec actualisation au taux de | B37: =+'Compte de tresorerie'!A24 -> 0.08 | C37: =+'Compte de tresorerie'!B51 -> 2 an(s) et 3 mois
A39: 6. Le taux de marge nette de la troisième année (résultat net / chiffre d'affaires) | B39: =+'Compte de tresorerie'!E11/'Ratios d''analyse'!D13 -> 0.20986838

Sheet PLAN DE TRESORERIE
A2: Rubriques | B2: Année 0 (mise en œuvre) | C2: Mois 1 | D2: Mois 2 | E2: Mois 3 | F2: Mois 4 | G2: Mois 5 | H2: Mois 6 | I2: Mois 7 | J2: Mois 8 | K2: Mois 9 | L2: Mois 10 | M2: Mois 11 | N2: Mois 12
A4: Apport personnel | B4: =+'Compte de tresorerie'!B6 -> 500000 | D4: =+C4 -> 0 | E4: =+D4 -> 0 | O4: =+B4='Compte de tresorerie'!B6 -> TRUE
A5: Crédit | B5: =+'Compte de tresorerie'!B7 -> 3000000 | D5: =C5 -> 0 | E5: =D5 -> 0 | H5: =G5 -> 0 | I5: =H5 -> 0 | J5: =I5 -> 0 | K5: =J5 -> 0 | L5: =K5 -> 0 | M5: =L5 -> 0 | N5: =M5 -> 0 | O5: =+B5='Compte de tresorerie'!B7 -> TRUE
A6: Contribution (Primes) FACEJ | B6: =+'Compte de tresorerie'!B8 -> 0 | D6: =C6 -> 0 | E6: =D6 -> 0 | O6: =+B6='Compte de tresorerie'!B8 -> TRUE
A7: Subvention (Projet Vert/verdissement) | B7: =+'Compte de tresorerie'!B9 -> 1500000 | D7: =C7 -> 0 | E7: =D7 -> 0 | O7: =+B7='Compte de tresorerie'!B9 -> TRUE
A8: Dotation aux Amortissements | B8: =+'Compte de tresorerie'!B10 -> 0 | C8: =+'Compte de tresorerie'!C10/12 -> 80743.056 | D8: =C8 -> 80743.056 | E8: =D8 -> 80743.056 | F8: =+E8 -> 80743.056 | G8: =+F8 -> 80743.056 | H8: =+G8 -> 80743.056 | I8: =+H8 -> 80743.056 | J8: =+I8 -> 80743.056 | K8: =+J8 -> 80743.056 | L8: =+K8 -> 80743.056 | M8: =+L8 -> 80743.056 | N8: =+M8 -> 80743.056 | O8: =SUM(C8:N8)='Compte de tresorerie'!C10 -> TRUE
A9: Résultats nets | B9: =+'Compte de tresorerie'!B11 -> 0 | C9: =+'Compte de tresorerie'!C11/12 -> 126400.88 | D9: =C9 -> 126400.88 | E9: =D9 -> 126400.88 | F9: =+E9 -> 126400.88 | G9: =+F9 -> 126400.88 | H9: =+G9 -> 126400.88 | I9: =+H9 -> 126400.88 | J9: =+I9 -> 126400.88 | K9: =+J9 -> 126400.88 | L9: =+K9 -> 126400.88 | M9: =+L9 -> 126400.88 | N9: =+M9 -> 126400.88 | O9: =SUM(C9:N9)='Compte de tresorerie'!C11 -> TRUE
A10: Total des Entrées | C10: =SUM(C3:C9) -> 207143.94 | D10: =SUM(D3:D9) -> 207143.94 | E10: =SUM(E3:E9) -> 207143.94 | F10: =SUM(F3:F9) -> 207143.94 | G10: =SUM(G3:G9) -> 207143.94 | H10: =SUM(H3:H9) -> 207143.94 | I10: =SUM(I3:I9) -> 207143.94 | J10: =SUM(J3:J9) -> 207143.94 | ... N10: =SUM(N3:N9) -> 207143.94
A11: Frais d'établissements | B11: =+'Compte de tresorerie'!B14 -> 15000 | D11: =C11 -> 0 | E11: =D11 -> 0 | F11: =E11 -> 0 | G11: =F11 -> 0 | H11: =G11 -> 0 | I11: =H11 -> 0 | J11: =I11 -> 0 | K11: =J11 -> 0 | ... N11: =M11 -> 0
A12: Frais d'investissement | B12: =+'Compte de tresorerie'!B15 -> 3985000
A13: BFR | B13: =+'Compte de tresorerie'!B16 -> 1000000
A14: Remboursement de CREDIT MOYEN TERME | C14: =+'Compte de tresorerie'!C17/12 -> 68181.818 | D14: =+C14 -> 68181.818 | E14: =+D14 -> 68181.818 | F14: =+E14 -> 68181.818 | G14: =+F14 -> 68181.818 | H14: =+G14 -> 68181.818 | I14: =+H14 -> 68181.818 | J14: =+I14 -> 68181.818 | K14: =+J14 -> 68181.818 | ... N14: =+M14 -> 68181.818
A15: Total des dépenses | B15: =SUM(B11:B14) -> 5000000 | C15: =SUM(C11:C14) -> 68181.818 | D15: =SUM(D11:D14) -> 68181.818 | E15: =SUM(E11:E14) -> 68181.818 | F15: =SUM(F11:F14) -> 68181.818 | G15: =SUM(G11:G14) -> 68181.818 | H15: =SUM(H11:H14) -> 68181.818 | I15: =SUM(I11:I14) -> 68181.818 | ... N15: =SUM(N11:N14) -> 68181.818
A17: Argent disponible en fin de mois | C17: =C10-C15 -> 138962.12 | D17: =D10-D15 -> 138962.12 | E17: =E10-E15 -> 138962.12 | F17: =F10-F15 -> 138962.12 | G17: =G10-G15 -> 138962.12 | H17: =H10-H15 -> 138962.12 | I17: =I10-I15 -> 138962.12 | J17: =J10-J15 -> 138962.12 | ... N17: =N10-N15 -> 138962.12
A19: Trésorérie cumulée | C19: =C17 -> 138962.12 | D19: =C19+D17 -> 277924.24 | E19: =D19+E17 -> 416886.36 | F19: =E19+F17 -> 555848.48 | G19: =F19+G17 -> 694810.61 | H19: =G19+H17 -> 833772.73 | I19: =H19+I17 -> 972734.85 | J19: =I19+J17 -> 1111697 | K19: =J19+K17 -> 1250659.1 | ... N19: =M19+N17 -> 1667545.5 | O19: =+N19='Compte de tresorerie'!C21 -> TRUE

Sheet COMPTE D'EXPLOITATION MENSUEL
A2: Désignation | B2: Mois 1 | C2: Mois 2 | D2: Mois 3 | E2: Mois 4 | F2: Mois 5 | G2: Mois 6 | H2: Mois 7 | I2: Mois 8 | J2: Mois 9 | K2: Mois 10 | L2: Mois 11 | M2: Mois 12
A3: Produits
A4: =+'Eléments du compte d''exploitati'!A7 -> Vente pastèque gros calibre | B4: =+'Eléments du compte d''exploitati'!B7/12 -> 466666.67 | C4: =B4 -> 466666.67 | D4: =C4 -> 466666.67 | E4: =D4 -> 466666.67 | F4: =E4 -> 466666.67 | G4: =F4 -> 466666.67 | H4: =G4 -> 466666.67 | I4: =H4 -> 466666.67 | J4: =I4 -> 466666.67 | ... M4: =L4 -> 466666.67 | N4: =+SUM(B4:M4)='Eléments du compte d''exploitati'!B7 -> TRUE
A5: =+'Eléments du compte d''exploitati'!A8 -> Vente pastèque moyen calibre | B5: =+'Eléments du compte d''exploitati'!B8/12 -> 150000 | C5: =B5 -> 150000 | D5: =C5 -> 150000 | E5: =D5 -> 150000 | F5: =E5 -> 150000 | G5: =F5 -> 150000 | H5: =G5 -> 150000 | I5: =H5 -> 150000 | J5: =I5 -> 150000 | ... M5: =L5 -> 150000 | N5: =+SUM(B5:M5)='Eléments du compte d''exploitati'!B8 -> TRUE
A6: =+'Eléments du compte d''exploitati'!A9 -> 0 | B6: =+'Eléments du compte d''exploitati'!B9/12 -> 0 | C6: =B6 -> 0 | D6: =C6 -> 0 | E6: =D6 -> 0 | F6: =E6 -> 0 | G6: =F6 -> 0 | H6: =G6 -> 0 | I6: =H6 -> 0 | J6: =I6 -> 0 | ... M6: =L6 -> 0 | N6: =+SUM(B6:M6)='Eléments du compte d''exploitati'!B9 -> TRUE
A7: =+'Eléments du compte d''exploitati'!A10 -> 0 | B7: =+'Eléments du compte d''exploitati'!B10/12 -> 0 | C7: =B7 -> 0 | D7: =C7 -> 0 | E7: =D7 -> 0 | F7: =E7 -> 0 | G7: =F7 -> 0 | H7: =G7 -> 0 | I7: =H7 -> 0 | J7: =I7 -> 0 | ... M7: =L7 -> 0 | N7: =+SUM(B7:M7)='Eléments du compte d''exploitati'!B10 -> TRUE
A8: =+'Eléments du compte d''exploitati'!A11 -> 0 | B8: =+'Eléments du compte d''exploitati'!B11/12 -> 0 | C8: =B8 -> 0 | D8: =C8 -> 0 | E8: =D8 -> 0 | F8: =E8 -> 0 | G8: =F8 -> 0 | H8: =G8 -> 0 | I8: =H8 -> 0 | J8: =I8 -> 0 | ... M8: =L8 -> 0 | N8: =+SUM(B8:M8)='Eléments du compte d''exploitati'!B11 -> TRUE
A9: Total des Produits | B9: =SUM(B4:B8) -> 616666.67 | C9: =SUM(C4:C8) -> 616666.67 | D9: =SUM(D4:D8) -> 616666.67 | E9: =SUM(E4:E8) -> 616666.67 | F9: =SUM(F4:F8) -> 616666.67 | G9: =SUM(G4:G8) -> 616666.67 | H9: =SUM(H4:H8) -> 616666.67 | I9: =SUM(I4:I8) -> 616666.67 | ... M9: =SUM(M4:M8) -> 616666.67
A10: Charges
A11: Matières premières | B11: =+'Compte d''exploitation'!B9/12 -> 160000 | C11: =B11 -> 160000 | D11: =C11 -> 160000 | E11: =D11 -> 160000 | F11: =E11 -> 160000 | G11: =F11 -> 160000 | H11: =G11 -> 160000 | I11: =H11 -> 160000 | J11: =I11 -> 160000 | ... M11: =L11 -> 160000 | N11: =+SUM(B11:M11)='Compte d''exploitation'!B9 -> TRUE
A12: =+'Compte d''exploitation'!A10 -> Charges de Personnel | B12: =+'Compte d''exploitation'!B10/12 -> 175000 | C12: =B12 -> 175000 | D12: =C12 -> 175000 | E12: =D12 -> 175000 | F12: =E12 -> 175000 | G12: =F12 -> 175000 | H12: =G12 -> 175000 | I12: =H12 -> 175000 | J12: =I12 -> 175000 | ... M12: =L12 -> 175000 | N12: =+SUM(B12:M12)='Compte d''exploitation'!B10 -> TRUE
A13: =+'Compte d''exploitation'!A19 -> Impôts et taxes | B13: =+'Compte d''exploitation'!B19/12 -> 15750 | C13: =B13 -> 15750 | D13: =C13 -> 15750 | E13: =D13 -> 15750 | F13: =E13 -> 15750 | G13: =F13 -> 15750 | H13: =G13 -> 15750 | I13: =H13 -> 15750 | J13: =I13 -> 15750 | ... M13: =L13 -> 15750 | N13: =+SUM(B13:M13)='Compte d''exploitation'!B19 -> TRUE
A14: =+'Compte d''exploitation'!A11 -> Travaux-Fournitures et Services Extérieurs (TFSE) | B14: =+'Compte d''exploitation'!B11/12 -> 37500 | C14: =B14 -> 37500 | D14: =C14 -> 37500 | E14: =D14 -> 37500 | F14: =E14 -> 37500 | G14: =F14 -> 37500 | H14: =G14 -> 37500 | I14: =H14 -> 37500 | J14: =I14 -> 37500 | ... M14: =L14 -> 37500 | N14: =+SUM(B14:M14)='Compte d''exploitation'!B11 -> TRUE
A15: =+'Compte d''exploitation'!A12 -> Autres charges | B15: =+'Compte d''exploitation'!B12/12 -> 0 | C15: =B15 -> 0 | D15: =C15 -> 0 | E15: =D15 -> 0 | F15: =E15 -> 0 | G15: =F15 -> 0 | H15: =G15 -> 0 | I15: =H15 -> 0 | J15: =I15 -> 0 | ... M15: =L15 -> 0 | N15: =+SUM(B15:M15)='Compte d''exploitation'!B12 -> TRUE
A16: =+'Compte d''exploitation'!A13 -> Frais financiers et charges assimilées | B16: =+'Compte d''exploitation'!B13/12 -> 21272.727 | C16: =B16 -> 21272.727 | D16: =C16 -> 21272.727 | E16: =D16 -> 21272.727 | F16: =E16 -> 21272.727 | G16: =F16 -> 21272.727 | H16: =G16 -> 21272.727 | I16: =H16 -> 21272.727 | J16: =I16 -> 21272.727 | ... M16: =L16 -> 21272.727 | N16: =+SUM(B16:M16)='Compte d''exploitation'!B13 -> TRUE
A17: Amortissement | B17: =+'Compte d''exploitation'!B14/12 -> 80743.056 | C17: =B17 -> 80743.056 | D17: =C17 -> 80743.056 | E17: =D17 -> 80743.056 | F17: =E17 -> 80743.056 | G17: =F17 -> 80743.056 | H17: =G17 -> 80743.056 | I17: =H17 -> 80743.056 | J17: =I17 -> 80743.056 | ... M17: =L17 -> 80743.056 | N17: =+SUM(B17:M17)='Compte d''exploitation'!B14 -> TRUE
A18: Total des charges | B18: =SUM(B11:B17) -> 490265.78 | C18: =SUM(C11:C17) -> 490265.78 | D18: =SUM(D11:D17) -> 490265.78 | E18: =SUM(E11:E17) -> 490265.78 | F18: =SUM(F11:F17) -> 490265.78 | G18: =SUM(G11:G17) -> 490265.78 | H18: =SUM(H11:H17) -> 490265.78 | I18: =SUM(I11:I17) -> 490265.78 | ... M18: =SUM(M11:M17) -> 490265.78
A20: Résultat Brut | B20: =B9-B18 -> 126400.88 | C20: =C9-C18 -> 126400.88 | D20: =D9-D18 -> 126400.88 | E20: =E9-E18 -> 126400.88 | F20: =F9-F18 -> 126400.88 | G20: =G9-G18 -> 126400.88 | H20: =H9-H18 -> 126400.88 | I20: =I9-I18 -> 126400.88 | ... M20: =M9-M18 -> 126400.88
A21: =+'Compte d''exploitation'!A18 -> BIC | B21: =+'Compte d''exploitation'!B18/12 -> 0 | C21: =B21 -> 0 | D21: =C21 -> 0 | E21: =D21 -> 0 | F21: =E21 -> 0 | G21: =F21 -> 0 | H21: =G21 -> 0 | I21: =H21 -> 0 | J21: =I21 -> 0 | ... M21: =L21 -> 0
A23: Résultat | B23: =B20-B21 -> 126400.88 | C23: =C20-C21 -> 126400.88 | D23: =D20-D21 -> 126400.88 | E23: =E20-E21 -> 126400.88 | F23: =F20-F21 -> 126400.88 | G23: =G20-G21 -> 126400.88 | H23: =H20-H21 -> 126400.88 | I23: =I20-I21 -> 126400.88 | ... M23: =M20-M21 -> 126400.88

Sheet Fiche Signalétique
A1: FICHE SIGNALETIQUE
A3: I. Financement du Projet
A4: Coût Total du projet | C4: =+D4/D4 -> 1 | D4: =+'Coût du projet'!C46 -> 5000000
A5: Montant de l’apport personnel (……..%) | C5: =+D5/D4 -> 0.1 | D5: =+'Plan Financement'!C7 -> 500000
A6: Montant des subventions et prime accordées (……%) | B6: Subvention emploi | C6: =+'Plan Financement'!B11 -> 0 | D6: =+'Plan Financement'!C11 -> 0
B7: Subvention innovation | C7: =+'Plan Financement'!B12 -> 0 | D7: =+'Plan Financement'!C12 -> 0
B8: Prime crédit | C8: =+'Plan Financement'!B17 -> 0 | D8: =+'Plan Financement'!C17 -> 0
A9: Montant des subventions (Projet Vert ou Verdissement) | B9: Subvention | C9: =+'Plan Financement'!B13 -> 0.3 | D9: =+'Plan Financement'!C13 -> 1500000
A10: Montant du crédit de financement sollicité (…. %) | B10: Crédit Moyen Terme | C10: =+D10/D4 -> 0.6 | D10: =+IF('Plan Financement'!B19<36,0,'Plan Financement'!C15) -> 3000000
B11: Crédit Court Terme | C11: =+D11/D4 -> 0 | D11: =+IF('Plan Financement'!B19<36,'Plan Financement'!C15,0) -> 0
A12: II. Conditions de financement du crédit
A13: Institution de financement | B13: (Nom de l’IFP) | C13: (à renseigner)
A14: Numéro de compte bancaire
A15: Durée du prêt | B15: (Années et mois) | C15: =+'Plan Financement'!B19 -> 36
A16: Taux du prêt | B16: Taux du crédit Moyen terme | C16: =+'Plan Financement'!B20 -> 0.08
B17: Taux du crédit Court terme
A18: III. Données économiques
A19: Chiffre d’affaires de référence (Entreprise en croissance) | B19: (Année 0) | D19: F.CFA
A20: Chiffres d’affaires prévisionnel | B20: 1ère année | C20: =+'Eléments du compte d''exploitati'!B12 -> 7400000 | D20: F.CFA
B21: 2ème année | C21: =+'Eléments du compte d''exploitati'!C12 -> 7548000 | D21: F.CFA
B22: 3ème année | C22: =+'Eléments du compte d''exploitati'!D12 -> 7698960 | D22: F.CFA
A23: Résultats Nets | B23: 1ère année | C23: =+'Compte d''exploitation'!B20 -> 1516810.6 | D23: F.CFA
B24: 2ème année | C24: =+'Compte d''exploitation'!C20 -> 1525515.2 | D24: F.CFA
B25: 3ème année | C25: =+'Compte d''exploitation'!D20 -> 1615768.2 | D25: F.CFA
A26: Capacité d’autofinancement | B26: 1ère année | C26: =+'Compte d''exploitation'!B22 -> 2485727.3 | D26: F.CFA
B27: 2ème année | C27: =+'Compte d''exploitation'!C22 -> 2479431.8 | D27: F.CFA
B28: 3ème année | C28: =+'Compte d''exploitation'!D22 -> 2569684.9 | D28: F.CFA
A29: IV. Quelques ratios
A30: Seuil de Rentabilité | C30: =+'Ratios d''analyse'!B29*100 -> 67.867431 | D30: %
A31: Valeur ajoutée | C31: =+'Ratios d''analyse'!C17*100 -> 66.687631 | D31: %
A32: TRI | C32: =+'Ratios d''analyse'!B31*100 -> 41.553744 | D32: %
